Workbook
Name zoeklijst: Trefwoorden!$A$2:$B$6

Sheet Data
A1: datum | B1: maand | C1: bedrag | D1: categorie | E1: omschrijving | F1: in/uitgave | G1: Bedrag +/- | H1: vast/variabel | I1: controle
A2: 45658 | B2: =TEXT(A2,"mmmm ") -> januari | C2: 2693.39 | D2: {=IFERROR( _xlfn.XLOOKUP(TRUE, ISNUMBER(FIND(Trefwoorden!$A$2:$A$99, E2)), Trefwoorden!$B$2:$B$99), "Onbekend" )} -> Inkomsten Loon | E2: OVERSCHRIJVING VAN 30-12 BE64 3751 1173 1652 BANKIER OPDRACHTGEVER: BBRUBEBB VVM DE LIJN ALGEMENE REK /A/ 29076 LOON VVM 12/2024 | F2: =VLOOKUP(Tabel1[[#This Row],[categorie]],Lijst!A:C,3,FALSE) -> Inkomst | G2: =IF(F2="Uitgave", -ABS(C2), ABS(C2)) -> 2693.39 | H2: =VLOOKUP(Tabel1[[#This Row],[categorie]],Lijst!A:B,2,FALSE) -> Inkomsten | I2: =IF(OR(AND(F2="Uitgave", C2<0), AND(F2="Inkomst", C2>0)), "OK", "FOUT") -> OK
A3: 45658 | B3: =TEXT(A3,"mmmm ") -> januari | C3: 2186.96 | D3: {=IFERROR( _xlfn.XLOOKUP(TRUE, ISNUMBER(FIND(Trefwoorden!$A$2:$A$99, E3)), Trefwoorden!$B$2:$B$99), "Onbekend" )} -> Inkomsten Loon | E3: OVERSCHRIJVING VAN 31-12 BE57 3751 1109 9435 BANKIER OPDRACHTGEVER: BBRUBEBB OV HULPREKENING /A/E002543 - 19303221177-118257-311 BETALING-12/2024- -- REFERENTIE: 241201-002543-/A/E002543 | F3: inkomst | G3: =IF(F3="Uitgave", -ABS(C3), ABS(C3)) -> 2186.96 | H3: =VLOOKUP(Tabel1[[#This Row],[categorie]],Lijst!A:B,2,FALSE) -> Inkomsten | I3: =IF(OR(AND(F3="Uitgave", C3<0), AND(F3="Inkomst", C3>0)), "OK", "FOUT") -> OK
A4: 45658 | B4: =TEXT(A4,"mmmm ") -> januari | C4: 70 | D4: Ouders Bram | F4: Inkomst | G4: =IF(F4="Uitgave", -ABS(C4), ABS(C4)) -> 70 | H4: =VLOOKUP(Tabel1[[#This Row],[categorie]],Lijst!A:B,2,FALSE) -> Variabel | I4: =IF(OR(AND(F4="Uitgave", C4<0), AND(F4="Inkomst", C4>0)), "OK", "FOUT") -> OK
A5: 45659 | B5: =TEXT(A5,"mmmm ") -> januari | C5: -65.85 | D5: voeding | F5: Uitgave | G5: =IF(F5="Uitgave", -ABS(C5), ABS(C5)) -> -65.85 | H5: =VLOOKUP(Tabel1[[#This Row],[categorie]],Lijst!A:B,2,FALSE) -> Vast | I5: =IF(OR(AND(F5="Uitgave", C5<0), AND(F5="Inkomst", C5>0)), "OK", "FOUT") -> OK
A6: 45659 | B6: =TEXT(A6,"mmmm ") -> januari | C6: -42.81 | D6: voeding | F6: Uitgave | G6: =IF(F6="Uitgave", -ABS(C6), ABS(C6)) -> -42.81 | H6: =VLOOKUP(Tabel1[[#This Row],[categorie]],Lijst!A:B,2,FALSE) -> Vast | I6: =IF(OR(AND(F6="Uitgave", C6<0), AND(F6="Inkomst", C6>0)), "OK", "FOUT") -> OK
A7: 45659 | B7: =TEXT(A7,"mmmm ") -> januari | C7: -40.62 | D7: Hospitalisatie | F7: Uitgave | G7: =IF(F7="Uitgave", -ABS(C7), ABS(C7)) -> -40.62 | H7: =VLOOKUP(Tabel1[[#This Row],[categorie]],Lijst!A:B,2,FALSE) -> Vast | I7: =IF(OR(AND(F7="Uitgave", C7<0), AND(F7="Inkomst", C7>0)), "OK", "FOUT") -> OK
A8: 45659 | B8: =TEXT(A8,"mmmm ") -> januari | C8: -30.79 | D8: voeding | F8: Uitgave | G8: =IF(F8="Uitgave", -ABS(C8), ABS(C8)) -> -30.79 | H8: =VLOOKUP(Tabel1[[#This Row],[categorie]],Lijst!A:B,2,FALSE) -> Vast | I8: =IF(OR(AND(F8="Uitgave", C8<0), AND(F8="Inkomst", C8>0)), "OK", "FOUT") -> OK
A9: 45659 | B9: =TEXT(A9,"mmmm ") -> januari | C9: -13.15 | D9: Laadbeurt | F9: Uitgave | G9: =IF(F9="Uitgave", -ABS(C9), ABS(C9)) -> -13.15 | H9: =VLOOKUP(Tabel1[[#This Row],[categorie]],Lijst!A:B,2,FALSE) -> Vast | I9: =IF(OR(AND(F9="Uitgave", C9<0), AND(F9="Inkomst", C9>0)), "OK", "FOUT") -> OK
A10: 45659 | B10: =TEXT(A10,"mmmm ") -> januari | C10: -11.25 | D10: voeding | F10: Uitgave | G10: =IF(F10="Uitgave", -ABS(C10), ABS(C10)) -> -11.25 | H10: =VLOOKUP(Tabel1[[#This Row],[categorie]],Lijst!A:B,2,FALSE) -> Vast | I10: =IF(OR(AND(F10="Uitgave", C10<0), AND(F10="Inkomst", C10>0)), "OK", "FOUT") -> OK
A11: 45659 | B11: =TEXT(A11,"mmmm ") -> januari | C11: -5 | D11: Laadbeurt | F11: Uitgave | G11: =IF(F11="Uitgave", -ABS(C11), ABS(C11)) -> -5 | H11: =VLOOKUP(Tabel1[[#This Row],[categorie]],Lijst!A:B,2,FALSE) -> Vast | I11: =IF(OR(AND(F11="Uitgave", C11<0), AND(F11="Inkomst", C11>0)), "OK", "FOUT") -> OK
A12: 45659 | B12: =TEXT(A12,"mmmm ") -> januari | C12: -3.27 | D12: voeding | F12: Uitgave | G12: =IF(F12="Uitgave", -ABS(C12), ABS(C12)) -> -3.27 | H12: =VLOOKUP(Tabel1[[#This Row],[categorie]],Lijst!A:B,2,FALSE) -> Vast | I12: =IF(OR(AND(F12="Uitgave", C12<0), AND(F12="Inkomst", C12>0)), "OK", "FOUT") -> OK
A13: 45659 | B13: =TEXT(A13,"mmmm ") -> januari | C13: -1 | D13: Parkeren | F13: Uitgave | G13: =IF(F13="Uitgave", -ABS(C13), ABS(C13)) -> -1 | H13: =VLOOKUP(Tabel1[[#This Row],[categorie]],Lijst!A:B,2,FALSE) -> Variabel | I13: =IF(OR(AND(F13="Uitgave", C13<0), AND(F13="Inkomst", C13>0)), "OK", "FOUT") -> OK
A14: 45660 | B14: =TEXT(A14,"mmmm ") -> januari | C14: -121.5 | D14: gas/elektriciteit | F14: Uitgave | G14: =IF(F14="Uitgave", -ABS(C14), ABS(C14)) -> -121.5 | H14: =VLOOKUP(Tabel1[[#This Row],[categorie]],Lijst!A:B,2,FALSE) -> Vast | I14: =IF(OR(AND(F14="Uitgave", C14<0), AND(F14="Inkomst", C14>0)), "OK", "FOUT") -> OK
A15: 45660 | B15: =TEXT(A15,"mmmm ") -> januari | C15: -65.95 | D15: school Bram | F15: Uitgave | G15: =IF(F15="Uitgave", -ABS(C15), ABS(C15)) -> -65.95 | H15: =VLOOKUP(Tabel1[[#This Row],[categorie]],Lijst!A:B,2,FALSE) -> Variabel | I15: =IF(OR(AND(F15="Uitgave", C15<0), AND(F15="Inkomst", C15>0)), "OK", "FOUT") -> OK
... A142: 45674 | B142: =TEXT(A142,"mmmm ") -> januari | C142: 0.94 | D142: kledij | F142: Inkomst | G142: =IF(F142="Uitgave", -ABS(C142), ABS(C142)) -> 0.94 | H142: =VLOOKUP(Tabel1[[#This Row],[categorie]],Lijst!A:B,2,FALSE) -> Variabel | I142: =IF(OR(AND(F142="Uitgave", C142<0), AND(F142="Inkomst", C142>0)), "OK", "FOUT") -> OK
A143: 45675 | B143: =TEXT(A143,"mmmm ") -> januari | C143: -194.4 | D143: restaurant | E143: keyaki | F143: Uitgave | G143: =IF(F143="Uitgave", -ABS(C143), ABS(C143)) -> -194.4 | H143: =VLOOKUP(Tabel1[[#This Row],[categorie]],Lijst!A:B,2,FALSE) -> Variabel | I143: =IF(OR(AND(F143="Uitgave", C143<0), AND(F143="Inkomst", C143>0)), "OK", "FOUT") -> OK
A144: 45675 | B144: =TEXT(A144,"mmmm ") -> januari | C144: -22.96 | D144: Coolblue | F144: Uitgave | G144: =IF(F144="Uitgave", -ABS(C144), ABS(C144)) -> -22.96 | H144: =VLOOKUP(Tabel1[[#This Row],[categorie]],Lijst!A:B,2,FALSE) -> Variabel | I144: =IF(OR(AND(F144="Uitgave", C144<0), AND(F144="Inkomst", C144>0)), "OK", "FOUT") -> OK
A145: 45675 | B145: =TEXT(A145,"mmmm ") -> januari | C145: 97 | D145: restaurant | F145: Inkomst | G145: =IF(F145="Uitgave", -ABS(C145), ABS(C145)) -> 97 | H145: =VLOOKUP(Tabel1[[#This Row],[categorie]],Lijst!A:B,2,FALSE) -> Variabel | I145: =IF(OR(AND(F145="Uitgave", C145<0), AND(F145="Inkomst", C145>0)), "OK", "FOUT") -> OK
A146: 45676 | B146: =TEXT(A146,"mmmm ") -> januari | C146: -122.14 | D146: school Bram | F146: Uitgave | G146: =IF(F146="Uitgave", -ABS(C146), ABS(C146)) -> -122.14 | H146: =VLOOKUP(Tabel1[[#This Row],[categorie]],Lijst!A:B,2,FALSE) -> Variabel | I146: =IF(OR(AND(F146="Uitgave", C146<0), AND(F146="Inkomst", C146>0)), "OK", "FOUT") -> OK
A147: 45677 | B147: =TEXT(A147,"mmmm ") -> januari | C147: -239.7 | D147: Louis/Vis | F147: Uitgave | G147: =IF(F147="Uitgave", -ABS(C147), ABS(C147)) -> -239.7 | H147: =VLOOKUP(Tabel1[[#This Row],[categorie]],Lijst!A:B,2,FALSE) -> Variabel | I147: =IF(OR(AND(F147="Uitgave", C147<0), AND(F147="Inkomst", C147>0)), "OK", "FOUT") -> OK
A148: 45677 | B148: =TEXT(A148,"mmmm ") -> januari | C148: -95.95 | D148: GSM Bram | F148: Uitgave | G148: =IF(F148="Uitgave", -ABS(C148), ABS(C148)) -> -95.95 | H148: =VLOOKUP(Tabel1[[#This Row],[categorie]],Lijst!A:B,2,FALSE) -> Vast | I148: =IF(OR(AND(F148="Uitgave", C148<0), AND(F148="Inkomst", C148>0)), "OK", "FOUT") -> OK
A149: 45677 | B149: =TEXT(A149,"mmmm ") -> januari | C149: -42.71 | D149: voeding | F149: Uitgave | G149: =IF(F149="Uitgave", -ABS(C149), ABS(C149)) -> -42.71 | H149: =VLOOKUP(Tabel1[[#This Row],[categorie]],Lijst!A:B,2,FALSE) -> Vast | I149: =IF(OR(AND(F149="Uitgave", C149<0), AND(F149="Inkomst", C149>0)), "OK", "FOUT") -> OK
A150: 45677 | B150: =TEXT(A150,"mmmm ") -> januari | C150: -33.55 | D150: Cardif | F150: Uitgave | G150: =IF(F150="Uitgave", -ABS(C150), ABS(C150)) -> -33.55 | H150: =VLOOKUP(Tabel1[[#This Row],[categorie]],Lijst!A:B,2,FALSE) -> Vast | I150: =IF(OR(AND(F150="Uitgave", C150<0), AND(F150="Inkomst", C150>0)), "OK", "FOUT") -> OK
A151: 45677 | B151: =TEXT(A151,"mmmm ") -> januari | C151: -27.85 | D151: restaurant | F151: Uitgave | G151: =IF(F151="Uitgave", -ABS(C151), ABS(C151)) -> -27.85 | H151: =VLOOKUP(Tabel1[[#This Row],[categorie]],Lijst!A:B,2,FALSE) -> Variabel | I151: =IF(OR(AND(F151="Uitgave", C151<0), AND(F151="Inkomst", C151>0)), "OK", "FOUT") -> OK
A152: 45677 | B152: =TEXT(A152,"mmmm ") -> januari | C152: -16 | D152: school Bram | F152: Uitgave | G152: =IF(F152="Uitgave", -ABS(C152), ABS(C152)) -> -16 | H152: =VLOOKUP(Tabel1[[#This Row],[categorie]],Lijst!A:B,2,FALSE) -> Variabel | I152: =IF(OR(AND(F152="Uitgave", C152<0), AND(F152="Inkomst", C152>0)), "OK", "FOUT") -> OK
A153: 45677 | B153: =TEXT(A153,"mmmm ") -> januari | C153: -13.99 | D153: voeding | F153: Uitgave | G153: =IF(F153="Uitgave", -ABS(C153), ABS(C153)) -> -13.99 | H153: =VLOOKUP(Tabel1[[#This Row],[categorie]],Lijst!A:B,2,FALSE) -> Vast | I153: =IF(OR(AND(F153="Uitgave", C153<0), AND(F153="Inkomst", C153>0)), "OK", "FOUT") -> OK
A154: 45677 | B154: =TEXT(A154,"mmmm ") -> januari | C154: -11.67 | D154: voeding | F154: Uitgave | G154: =IF(F154="Uitgave", -ABS(C154), ABS(C154)) -> -11.67 | H154: =VLOOKUP(Tabel1[[#This Row],[categorie]],Lijst!A:B,2,FALSE) -> Vast | I154: =IF(OR(AND(F154="Uitgave", C154<0), AND(F154="Inkomst", C154>0)), "OK", "FOUT") -> OK
A155: 45677 | B155: =TEXT(A155,"mmmm ") -> januari | C155: -9.35 | D155: Laadbeurt | F155: Uitgave | G155: =IF(F155="Uitgave", -ABS(C155), ABS(C155)) -> -9.35 | H155: =VLOOKUP(Tabel1[[#This Row],[categorie]],Lijst!A:B,2,FALSE) -> Vast | I155: =IF(OR(AND(F155="Uitgave", C155<0), AND(F155="Inkomst", C155>0)), "OK", "FOUT") -> OK
... A225: 45687 | B225: =TEXT(A225,"mmmm ") -> januari | C225: 600 | D225: Louis/Vis | F225: Inkomst | G225: =IF(F225="Uitgave", -ABS(C225), ABS(C225)) -> 600 | H225: =VLOOKUP(Tabel1[[#This Row],[categorie]],Lijst!A:B,2,FALSE) -> Variabel | I225: =IF(OR(AND(F225="Uitgave", C225<0), AND(F225="Inkomst", C225>0)), "OK", "FOUT") -> OK
A226: 45688 | B226: =TEXT(A226,"mmmm ") -> januari | C226: -44.64 | D226: {=IFERROR( _xlfn.XLOOKUP(TRUE, ISNUMBER(FIND(Trefwoorden!$A$2:$A$99, E226)), Trefwoorden!$B$2:$B$99), "Onbekend" )} -> Hospitalisatie | E226: EUROPESE DOMICILIERING 31-12 SCHULDEISER : KBC VERZEKERINGEN REF. SCHULDEISER: 390794481282 MANDAATREFERTE : L00194638787V0001 EIGEN OMSCHR. : HOSPITALISATIEVERZEKERING MEDEDELING : POL.54467509 31/12/2024-31/01/2025 HOSPITALISATIEVERZEKERING | F226: Uitgave | G226: =IF(F226="Uitgave", -ABS(C226), ABS(C226)) -> -44.64 | H226: =VLOOKUP(Tabel1[[#This Row],[categorie]],Lijst!A:B,2,FALSE) -> Vast | I226: =IF(OR(AND(F226="Uitgave", C226<0), AND(F226="Inkomst", C226>0)), "OK", "FOUT") -> OK
A227: 45688 | B227: =TEXT(A227,"mmmm ") -> januari | C227: -11.45 | D227: voeding | F227: Uitgave | G227: =IF(F227="Uitgave", -ABS(C227), ABS(C227)) -> -11.45 | H227: =VLOOKUP(Tabel1[[#This Row],[categorie]],Lijst!A:B,2,FALSE) -> Vast | I227: =IF(OR(AND(F227="Uitgave", C227<0), AND(F227="Inkomst", C227>0)), "OK", "FOUT") -> OK
A228: 45688 | B228: =TEXT(A228,"mmmm ") -> januari | C228: -6.28 | D228: voeding | F228: Uitgave | G228: =IF(F228="Uitgave", -ABS(C228), ABS(C228)) -> -6.28 | H228: =VLOOKUP(Tabel1[[#This Row],[categorie]],Lijst!A:B,2,FALSE) -> Vast | I228: =IF(OR(AND(F228="Uitgave", C228<0), AND(F228="Inkomst", C228>0)), "OK", "FOUT") -> OK
A229: 45688 | B229: =TEXT(A229,"mmmm ") -> januari | C229: -5.89 | D229: voeding | F229: Uitgave | G229: =IF(F229="Uitgave", -ABS(C229), ABS(C229)) -> -5.89 | H229: =VLOOKUP(Tabel1[[#This Row],[categorie]],Lijst!A:B,2,FALSE) -> Vast | I229: =IF(OR(AND(F229="Uitgave", C229<0), AND(F229="Inkomst", C229>0)), "OK", "FOUT") -> OK
A230: 45688 | B230: =TEXT(A230,"mmmm ") -> januari | C230: -4.9 | D230: voeding | F230: Uitgave | G230: =IF(F230="Uitgave", -ABS(C230), ABS(C230)) -> -4.9 | H230: =VLOOKUP(Tabel1[[#This Row],[categorie]],Lijst!A:B,2,FALSE) -> Vast | I230: =IF(OR(AND(F230="Uitgave", C230<0), AND(F230="Inkomst", C230>0)), "OK", "FOUT") -> OK
A231: 45688 | B231: =TEXT(A231,"mmmm ") -> januari | C231: -4 | D231: voeding | F231: Uitgave | G231: =IF(F231="Uitgave", -ABS(C231), ABS(C231)) -> -4 | H231: =VLOOKUP(Tabel1[[#This Row],[categorie]],Lijst!A:B,2,FALSE) -> Vast | I231: =IF(OR(AND(F231="Uitgave", C231<0), AND(F231="Inkomst", C231>0)), "OK", "FOUT") -> OK
A232: 45688 | B232: =TEXT(A232,"mmmm ") -> januari | C232: -3.9 | D232: voeding | F232: Uitgave | G232: =IF(F232="Uitgave", -ABS(C232), ABS(C232)) -> -3.9 | H232: =VLOOKUP(Tabel1[[#This Row],[categorie]],Lijst!A:B,2,FALSE) -> Vast | I232: =IF(OR(AND(F232="Uitgave", C232<0), AND(F232="Inkomst", C232>0)), "OK", "FOUT") -> OK
A233: 45688 | B233: =TEXT(A233,"mmmm ") -> januari | C233: -1.5 | D233: automaat De Lijn | F233: Uitgave | G233: =IF(F233="Uitgave", -ABS(C233), ABS(C233)) -> -1.5 | H233: =VLOOKUP(Tabel1[[#This Row],[categorie]],Lijst!A:B,2,FALSE) -> Variabel | I233: =IF(OR(AND(F233="Uitgave", C233<0), AND(F233="Inkomst", C233>0)), "OK", "FOUT") -> OK
A234: 45689 | B234: =TEXT(A234,"mmmm ") -> februari | C234: 2206.93 | D234: Inkomsten Loon | F234: Inkomst | G234: =IF(F234="Uitgave", -ABS(C234), ABS(C234)) -> 2206.93 | H234: =VLOOKUP(Tabel1[[#This Row],[categorie]],Lijst!A:B,2,FALSE) -> Inkomsten | I234: =IF(OR(AND(F234="Uitgave", C234<0), AND(F234="Inkomst", C234>0)), "OK", "FOUT") -> OK
A235: 45689 | B235: =TEXT(A235,"mmmm ") -> februari | C235: 2449.6 | D235: Inkomsten Loon | F235: Inkomst | G235: =IF(F235="Uitgave", -ABS(C235), ABS(C235)) -> 2449.6 | H235: =VLOOKUP(Tabel1[[#This Row],[categorie]],Lijst!A:B,2,FALSE) -> Inkomsten | I235: =IF(OR(AND(F235="Uitgave", C235<0), AND(F235="Inkomst", C235>0)), "OK", "FOUT") -> OK
...

Sheet Dashboard
A1: Financieel overzicht BoRoLo | T1: =DATE(2025,COLUMN()-3,1) -> 46143 | U1: =DATE(2025,COLUMN()-3,1) -> 46174 | V1: =DATE(2025,COLUMN()-3,1) -> 46204 | W1: =DATE(2025,COLUMN()-3,1) -> 46235 | X1: =DATE(2025,COLUMN()-3,1) -> 46266 | Y1: =DATE(2025,COLUMN()-3,1) -> 46296 | Z1: =DATE(2025,COLUMN()-3,1) -> 46327 | AA1: =DATE(2025,COLUMN()-3,1) -> 46357 | AB1: =DATE(2025,COLUMN()-3,1) -> 46388 | AC1: =DATE(2025,COLUMN()-2,1) -> 46447
A5: Som van Bedrag +/- | C5: maand | R5: SCORE | S5: =Score!E7 -> 70
A6: vast/variabel | B6: categorie | C6: januari | D6: februari | E6: maart | F6: april | G6: mei | H6: juni | I6: juli | J6: augustus | K6: september | L6: oktober | M6: november | N6: december | O6: Eindtotaal
A7: Inkomsten | B7: Inkomsten Loon | C7: 4880.35 | D7: 4656.53 | E7: 5546.02 | F7: 5108.93 | G7: 7249.02 | H7: 6896.63 | I7: 5039.74 | J7: 4526.28 | K7: 5638.08 | L7: 5258.81 | M7: 5120.21 | N7: 5123.73 | O7: 65044.33 | R7: Krediet | S7: =IF(Kredietscore!B8>=80,"✅ Kredietwaardig",IF(Kredietscore!B8>=50,"⚠️ Redelijk","❌ Risico")) -> ✅ Kredietwaardig
A8: Totaal Inkomsten | C8: 4880.35 | D8: 4656.53 | E8: 5546.02 | F8: 5108.93 | G8: 7249.02 | H8: 6896.63 | I8: 5039.74 | J8: 4526.28 | K8: 5638.08 | L8: 5258.81 | M8: 5120.21 | N8: 5123.73 | O8: 65044.33
A9: Vast | B9: hypotheek | C9: -810.65 | D9: -810.65 | E9: -810.65 | F9: -810.65 | G9: -810.65 | H9: -810.65 | I9: -810.65 | J9: -810.65 | K9: -810.65 | L9: -810.65 | M9: -810.65 | O9: -8917.15
B10: gas/elektriciteit | C10: -121.5 | D10: -127.5 | E10: -265.71 | F10: -142 | G10: 51.33 | H10: -108.31 | I10: -228.76 | J10: -84.37 | K10: 60 | L10: -108 | M10: -54 | O10: -1128.82
B11: Water | D11: -95.86 | F11: -159.85 | O11: -255.71
B12: voeding | C12: -728.74 | D12: -679.88 | E12: -1235.37 | F12: -924.11 | G12: -1037.95 | H12: -952.25 | I12: -1002.95 | J12: -469.15 | K12: -570.38 | L12: -785.25 | M12: -605.95 | O12: -8991.98
B13: Telenet | C13: -66.23 | E13: -136.27 | F13: -66.03 | G13: -69.65 | H13: -74.43 | I13: -76.83 | K13: -111.08 | L13: -61.83 | O13: -662.35
B14: Bankkost | D14: -1.5 | E14: -1.5 | F14: -11.49 | G14: -1.5 | H14: -1.5 | I14: -1.5 | J14: -1.5 | L14: -5.25 | M14: -5.25 | O14: -30.99
B15: belasting | E15: 3234.04 | H15: -310.06 | K15: -49 | O15: 2874.98
B16: GSM Bram | C16: -120.94 | D16: -126.92 | E16: -75.96 | F16: -44.98 | G16: -24.1 | H16: -53.22 | I16: -14.01 | J16: -10 | K16: -23 | L16: -23 | M16: -6 | O16: -522.13
B17: GSM Christoff | F17: -5 | G17: -5 | H17: -7.58 | I17: -5 | J17: -5 | K17: -5 | L17: -5 | M17: -6.21 | O17: -43.79
B18: Gezondheid | C18: -45.51 | D18: -175.74 | E18: -161.15 | F18: -232.26 | G18: -313.74 | H18: -375.81 | I18: -817.75 | J18: -411.27 | K18: -411.44 | L18: -672.45 | M18: -379.09 | O18: -3996.21
B19: Hospitalisatie | C19: -85.26 | D19: -85.26 | E19: -85.26 | F19: -85.26 | G19: -45.25 | H19: -134.53 | I19: -95.85 | J19: -45.25 | K19: -184.35 | L19: -50.6 | M19: -64.2 | O19: -961.07
B20: Leasing Auto | C20: -586.12 | D20: -586.12 | E20: -586.12 | F20: -586.12 | G20: -586.12 | H20: -586.12 | I20: -586.12 | J20: -586.12 | K20: -377.41 | L20: -586.12 | M20: -586.12 | O20: -6238.61
B21: afbetaling fiets | G21: -120 | H21: -125.81 | I21: -125.81 | J21: -125.81 | K21: -125.81 | L21: -125.81 | M21: -125.81 | O21: -874.86
B22: pensioensparen | C22: -166.66 | D22: -166.66 | E22: -166.66 | F22: -166.66 | G22: -166.66 | H22: -166.66 | I22: -171.66 | J22: -171.66 | K22: -171.66 | L22: -171.66 | M22: -171.66 | O22: -1858.26
B23: AXA | C23: -165.8 | D23: -165.8 | E23: -166.78 | F23: -166.78 | G23: -166.78 | H23: -53.29 | I23: -166.78 | J23: -166.78 | K23: -174.27 | L23: -174.27 | M23: -174.27 | O23: -1741.6
B24: omnium | H24: -113.49 | O24: -113.49
B25: vakbond | C25: -20.71 | D25: 122.29 | E25: -20.71 | F25: -20.71 | G25: -20.71 | H25: -20.71 | I25: -20.71 | J25: -20.71 | K25: -20.71 | L25: -20.71 | M25: -20.71 | O25: -84.81
B26: verzekering | E26: -33.55 | H26: -45.56 | O26: -79.11
B27: Euromex | C27: -12.01 | D27: -12.01 | E27: -12.01 | F27: -12.01 | G27: -12.01 | I27: -12.01 | J27: -12.01 | K27: -12.01 | L27: -12.01 | M27: -12.01 | O27: -120.1
B28: Cardif | C28: -33.55 | D28: -33.55 | F28: -33.55 | G28: -33.55 | I28: -33.55 | J28: -33.55 | K28: -33.55 | L28: -33.55 | O28: -268.4
B29: Laadbeurt | C29: -213.52 | D29: -168.53 | E29: -132.5 | F29: -149.3 | G29: -104.18 | H29: -90.45 | I29: -122.05 | J29: -115.33 | K29: -175.56 | L29: -157.42 | M29: -203.19 | O29: -1632.03
B30: krant | C30: -11.95 | D30: -11.95 | E30: -5.62 | F30: -12 | G30: -12 | H30: -12 | O30: -65.52
B31: kapster | C31: -25 | D31: -25 | E31: -50 | F31: -25 | G31: -25 | I31: -25 | J31: -50 | K31: -25 | L31: -25 | M31: -25 | O31: -300
A32: Totaal Vast | C32: -3214.15 | D32: -3150.64 | E32: -711.78 | F32: -3653.76 | G32: -3503.52 | H32: -4042.43 | I32: -4316.99 | J32: -3119.16 | K32: -3220.88 | L32: -3828.58 | M32: -3250.12 | O32: -36012.01
A33: Variabel | B33: Allerlei | C33: -29.1 | D33: 117.21 | E33: -189.31 | F33: -130.27 | G33: 154.4 | H33: -11.98 | I33: -22.58 | J33: -99.59 | K33: -132.65 | L33: -117.04 | M33: 18.21 | O33: -442.7
B34: Action | G34: -0.99 | H34: -43.96 | I34: -25.09 | J34: -17.79 | K34: -20.06 | L34: -16.15 | M34: -9.36 | O34: -133.4
B35: Amazon | G35: -89.17 | H35: -52.05 | I35: -49.99 | O35: -191.21
B36: automaat De Lijn | C36: -27.9 | D36: -56.9 | E36: -41.3 | F36: -36.4 | G36: -22.5 | H36: -15.2 | I36: -11.9 | J36: -19.6 | K36: -41.2 | L36: -36.5 | M36: -33.8 | O36: -343.2
B37: AVA | F37: -10.28 | H37: -3.1 | K37: -2.99 | O37: -16.37
B38: Bol | C38: -45.89 | D38: -22.89 | F38: -5.5 | G38: -14.99 | H38: -44.95 | I38: 0 | K38: -82 | L38: -39.98 | M38: -104.43 | O38: -360.63
B39: Brico | C39: -13.08 | E39: -11.99 | H39: -16.58 | I39: -15.48 | J39: -28.4 | M39: -18.39 | O39: -103.92
B40: cadeautjes | E40: -34.5 | F40: -10 | J40: -26.5 | K40: -150 | L40: -80.7 | O40: -301.7
B41: car wash | C41: -13 | F41: -34 | G41: -35 | I41: -19 | M41: -13 | O41: -114
B42: Coolblue | C42: -60.95 | D42: -13.99 | E42: -90.99 | F42: -44.98 | G42: -120.99 | H42: -241.97 | I42: -43.99 | J42: -23.98 | K42: -29.99 | L42: -85 | M42: -135.99 | O42: -892.82
B43: Deborah/nieuwkuis | C43: -25 | O43: -25
...

Sheet Budgetten
A1: Som van Bedrag +/- | B1: Kolomlabels
A2: Rijlabels | B2: Inkomsten Loon | C2: voeding | D2: hypotheek | E2: Leasing Auto | F2: gas/elektriciteit | G2: Water | H2: Hospitalisatie | I2: school Bram | J2: Telenet | K2: Louis/Vis | L2: GSM Bram | M2: GSM Christoff | N2: AXA | O2: pensioensparen | P2: afbetaling fiets | Q2: belasting | R2: Allerlei | S2: Parkeren | T2: verzekering | U2: restaurant | V2: Euromex | W2: Cardif | X2: Gezondheid | Y2: vakbond | Z2: Action | AA2: Amazon | AB2: automaat De Lijn | AC2: uitstapkes | AD2: AVA | AE2: kledij | AF2: Bankkost | AG2: Bol | AH2: Brico | AI2: car wash | AJ2: Coolblue | AK2: Deborah/nieuwkuis | AL2: decathlon | AM2: DPG | AN2: Dreamland | AO2: EuroShop | AP2: Gamma | AQ2: Hema | AR2: ICT | AS2: Ikea | AT2: Jysk | AU2: kapster | AV2: Koffie | AW2: krant | AX2: kruidvat | AY2: Laadbeurt | AZ2: visa | BA2: Laserontharing | BB2: Mediahuis | BC2: molecule | BD2: NMBS | BE2: omnium | BF2: Onderhoud huis | BG2: Ramenwas | BH2: Rituals | BI2: standaardboekhandel | BJ2: Streamz | BK2: trein | BL2: cadeautjes | BM2: dietiste | BN2: Ouders Bram | BO2: 0 | BP2: Zwemmen | BQ2: Auto onderhoud | BR2: Eindtotaal
A3: januari | B3: 4880.35 | C3: -728.74 | D3: -810.65 | E3: -586.12 | F3: -121.5 | H3: -85.26 | I3: -320.26 | J3: -66.23 | K3: -1617.73 | L3: -120.94 | N3: -165.8 | O3: -166.66 | R3: -29.1 | S3: -17.59 | U3: -343.42 | V3: -12.01 | W3: -33.55 | X3: -45.51 | Y3: -20.71 | AB3: -27.9 | AC3: -192.7 | AE3: 0.93 | AG3: -45.89 | AH3: -13.08 | AI3: -13 | AJ3: -60.95 | AK3: -25 | AO3: -29.15 | AR3: 390.33 | AS3: -92.96 | AU3: -25 | AW3: -11.95 | AX3: -12.48 | AY3: -213.52 | BA3: -150 | BD3: -3.3 | BJ3: -12.95 | BN3: 70 | BR3: -880
A4: februari | B4: 4656.53 | C4: -679.88 | D4: -810.65 | E4: -586.12 | F4: -127.5 | G4: -95.86 | H4: -85.26 | I4: -49.22 | K4: -2508.67 | L4: -126.92 | N4: -165.8 | O4: -166.66 | R4: 117.21 | U4: -296.08 | V4: -12.01 | W4: -33.55 | X4: -175.74 | Y4: 122.29 | AB4: -56.9 | AE4: -17.9 | AF4: -1.5 | AG4: -22.89 | AJ4: -13.99 | AO4: -28.7 | AS4: -82.12 | AU4: -25 | AW4: -11.95 | AY4: -168.53 | BA4: -60 | BG4: -84.7 | BJ4: -197.33 | BR4: -1795.4
A5: maart | B5: 5546.02 | C5: -1235.37 | D5: -810.65 | E5: -586.12 | F5: -265.71 | H5: -85.26 | I5: -143.57 | J5: -136.27 | K5: -729.38 | L5: -75.96 | N5: -166.78 | O5: -166.66 | Q5: 3234.04 | R5: -189.31 | S5: -12.5 | T5: -33.55 | U5: -531.63 | V5: -12.01 | X5: -161.15 | Y5: -20.71 | AB5: -41.3 | AE5: -17.5 | AF5: -1.5 | AH5: -11.99 | AJ5: -90.99 | AO5: -5.95 | AQ5: -5.09 | AR5: -196.95 | AS5: -38.74 | AU5: -50 | AV5: -40.8 | AW5: -5.62 | AY5: -132.5 | BD5: -7 | BL5: -34.5 | BN5: -26.5 | BR5: 2710.54
A6: april | B6: 5108.93 | C6: -924.11 | D6: -810.65 | E6: -586.12 | F6: -142 | G6: -159.85 | H6: -85.26 | I6: -168.9 | J6: -66.03 | K6: -326.03 | L6: -44.98 | M6: -5 | N6: -166.78 | O6: -166.66 | R6: -130.27 | S6: -38.5 | U6: -536.44 | V6: -12.01 | W6: -33.55 | X6: -232.26 | Y6: -20.71 | AB6: -36.4 | AC6: -317.25 | AD6: -10.28 | AE6: -166.37 | AF6: -11.49 | AG6: -5.5 | AI6: -34 | AJ6: -44.98 | AL6: -7 | AN6: -81.8 | AR6: -21.78 | AU6: -25 | AV6: -49.6 | AW6: -12 | AY6: -149.3 | AZ6: -363.29 | BA6: -150 | BC6: -50.8 | BD6: 7 | BF6: -201.19 | BL6: -10 | BN6: 31 | BR6: -1257.21
A7: mei | B7: 7249.02 | C7: -1037.95 | D7: -810.65 | E7: -586.12 | F7: 51.33 | H7: -45.25 | I7: -162.84 | J7: -69.65 | K7: -240.34 | L7: -24.1 | M7: -5 | N7: -166.78 | O7: -166.66 | P7: -120 | R7: 154.4 | S7: -9 | U7: -454.13 | V7: -12.01 | W7: -33.55 | X7: -313.74 | Y7: -20.71 | Z7: -0.99 | AA7: -89.17 | AB7: -22.5 | AC7: -96.5 | AF7: -1.5 | AG7: -14.99 | AI7: -35 | AJ7: -120.99 | AL7: -20.5 | AM7: -59.41 | AO7: -25.9 | AT7: -45 | AU7: -25 | AW7: -12 | AX7: -24.99 | AY7: -104.18 | AZ7: -899.89 | BC7: -116.5 | BD7: -3.3 | BR7: 1457.96
A8: juni | B8: 6896.63 | C8: -952.25 | D8: -810.65 | E8: -586.12 | F8: -108.31 | H8: -134.53 | I8: -47.46 | J8: -74.43 | K8: -62 | L8: -53.22 | M8: -7.58 | N8: -53.29 | O8: -166.66 | P8: -125.81 | Q8: -310.06 | R8: -11.98 | S8: -12.35 | T8: -45.56 | U8: -80.29 | X8: -375.81 | Y8: -20.71 | Z8: -43.96 | AA8: -52.05 | AB8: -15.2 | AC8: -192.38 | AD8: -3.1 | AE8: -133.98 | AF8: -1.5 | AG8: -44.95 | AH8: -16.58 | AJ8: -241.97 | AO8: -71 | AP8: -46.65 | AR8: -69.98 | AW8: -12 | AX8: -14.68 | AY8: -90.45 | AZ8: -110.86 | BA8: -150 | BD8: -65 | BE8: -113.49 | BH8: -22.9 | BR8: 1344.88
A9: juli | B9: 5039.74 | C9: -1002.95 | D9: -810.65 | E9: -586.12 | F9: -228.76 | H9: -95.85 | I9: -78.49 | J9: -76.83 | K9: -207.27 | L9: -14.01 | M9: -5 | N9: -166.78 | O9: -171.66 | P9: -125.81 | R9: -22.58 | S9: -6.5 | U9: -176.85 | V9: -12.01 | W9: -33.55 | X9: -817.75 | Y9: -20.71 | Z9: -25.09 | AA9: -49.99 | AB9: -11.9 | AC9: -165.9 | AF9: -1.5 | AG9: 0 | AH9: -15.48 | AI9: -19 | AJ9: -43.99 | AL9: -8 | AO9: -35.2 | AQ9: -4.59 | AR9: 59.1 | AS9: -25.09 | AU9: -25 | AV9: -92.31 | AY9: -122.05 | AZ9: -48.95 | BB9: -12 | BC9: -17.85 | BD9: -12.1 | BK9: -85 | BM9: -24 | BN9: -25 | BR9: -431.28
A10: augustus | B10: 4526.28 | C10: -469.15 | D10: -810.65 | E10: -586.12 | F10: -84.37 | H10: -45.25 | I10: -380.15 | K10: -298.35 | L10: -10 | M10: -5 | N10: -166.78 | O10: -171.66 | P10: -125.81 | R10: -99.59 | U10: -361.08 | V10: -12.01 | W10: -33.55 | X10: -411.27 | Y10: -20.71 | Z10: -17.79 | AB10: -19.6 | AC10: -100.1 | AE10: -301.79 | AF10: -1.5 | AH10: -28.4 | AJ10: -23.98 | AL10: -2 | AO10: -20.95 | AQ10: -6.93 | AR10: -42.95 | AU10: -50 | AY10: -115.33 | BB10: -12 | BD10: -30.4 | BL10: -26.5 | BM10: -24 | BN10: -82 | BP10: -267 | BR10: -738.44
A11: september | B11: 5638.08 | C11: -570.38 | D11: -810.65 | E11: -377.41 | F11: 60 | H11: -184.35 | I11: -155.86 | J11: -111.08 | K11: -62 | L11: -23 | M11: -5 | N11: -174.27 | O11: -171.66 | P11: -125.81 | Q11: -49 | R11: -132.65 | S11: -2.9 | U11: -68.4 | V11: -12.01 | W11: -33.55 | X11: -411.44 | Y11: -20.71 | Z11: -20.06 | AB11: -41.2 | AC11: -24 | AD11: -2.99 | AE11: -499.85 | AG11: -82 | AJ11: -29.99 | AL11: -6 | AO11: -35.25 | AR11: -130.2 | AS11: -6.49 | AU11: -25 | AX11: -38.56 | AY11: -175.56 | AZ11: -248.67 | BA11: -60 | BB11: -12 | BI11: -21.5 | BL11: -150 | BO11: #N/A | BQ11: -131.71 | BR11: #N/A
A12: oktober | B12: 5258.81 | C12: -785.25 | D12: -810.65 | E12: -586.12 | F12: -108 | H12: -50.6 | I12: -10 | J12: -61.83 | K12: -141.57 | L12: -23 | M12: -5 | N12: -174.27 | O12: -171.66 | P12: -125.81 | R12: -117.04 | S12: -22.27 | U12: -415.23 | V12: -12.01 | W12: -33.55 | X12: -672.45 | Y12: -20.71 | Z12: -16.15 | AB12: -36.5 | AC12: -306.64 | AE12: -256.36 | AF12: -5.25 | AG12: -39.98 | AJ12: -85 | AO12: -2.5 | AQ12: -20.93 | AR12: -166.82 | AS12: -16.58 | AU12: -25 | AV12: -24.8 | AX12: -6.79 | AY12: -157.42 | AZ12: -150.69 | BA12: -150 | BB12: -12 | BC12: -17.8 | BL12: -80.7 | BM12: -52 | BN12: -527.4 | BR12: -1245.52
A13: november | B13: 5120.21 | C13: -605.95 | D13: -810.65 | E13: -586.12 | F13: -54 | H13: -64.2 | I13: -15.99 | K13: -92.51 | L13: -6 | M13: -6.21 | N13: -174.27 | O13: -171.66 | P13: -125.81 | R13: 18.21 | S13: -11.88 | U13: -251.25 | V13: -12.01 | X13: -379.09 | Y13: -20.71 | Z13: -9.36 | AB13: -33.8 | AC13: -18.7 | AE13: -354.28 | AF13: -5.25 | AG13: -104.43 | AH13: -18.39 | AI13: -13 | AJ13: -135.99 | AL13: -25 | AO13: -14 | AR13: -50.56 | AS13: -68.4 | AU13: -25 | AV13: -26.9 | AY13: -203.19 | AZ13: -58.69 | BA13: -90 | BB13: -12 | BR13: 483.17
A14: december | B14: 5123.73 | BR14: 5123.73
A15: Eindtotaal | B15: 65044.33 | C15: -8991.98 | D15: -8917.15 | E15: -6238.61 | F15: -1128.82 | G15: -255.71 | H15: -961.07 | I15: -1532.74 | J15: -662.35 | K15: -6285.85 | L15: -522.13 | M15: -43.79 | N15: -1741.6 | O15: -1858.26 | P15: -874.86 | Q15: 2874.98 | R15: -442.7 | S15: -133.49 | T15: -79.11 | U15: -3514.8 | V15: -120.1 | W15: -268.4 | X15: -3996.21 | Y15: -84.81 | Z15: -133.4 | AA15: -191.21 | AB15: -343.2 | AC15: -1414.17 | AD15: -16.37 | AE15: -1747.1 | AF15: -30.99 | AG15: -360.63 | AH15: -103.92 | AI15: -114 | AJ15: -892.82 | AK15: -25 | AL15: -68.5 | AM15: -59.41 | AN15: -81.8 | AO15: -268.6 | AP15: -46.65 | AQ15: -37.54 | AR15: -229.81 | AS15: -330.38 | AT15: -45 | AU15: -300 | AV15: -234.41 | AW15: -65.52 | AX15: -97.5 | AY15: -1632.03 | AZ15: -1881.04 | BA15: -810 | BB15: -60 | BC15: -202.95 | BD15: -114.1 | BE15: -113.49 | BF15: -201.19 | BG15: -84.7 | BH15: -22.9 | BI15: -21.5 | BJ15: -210.28 | BK15: -85 | BL15: -301.7 | BM15: -100 | BN15: -559.9 | BO15: #N/A | BP15: -267 | BQ15: -131.71 | BR15: #N/A
A17: Kolom1 | B17: Kolom2 | C17: Kolom3 | D17: Kolom4 | E17: Kolom5 | F17: Kolom6 | G17: Kolom7 | H17: Kolom8 | I17: Kolom9 | J17: Kolom10 | K17: Kolom11 | L17: Kolom12 | M17: Kolom13 | N17: Kolom14 | O17: Kolom15 | P17: Kolom16 | Q17: Kolom17 | R17: Kolom18 | S17: Kolom19 | T17: Kolom20 | U17: Kolom21 | V17: Kolom22 | W17: Kolom23 | X17: Kolom24 | Y17: Kolom25 | Z17: Kolom26 | AA17: Kolom27 | AB17: Kolom28 | AC17: Kolom29 | AD17: Kolom30 | AE17: Kolom31 | AF17: Kolom32 | AG17: Kolom33 | AH17: Kolom34 | AI17: Kolom35 | AJ17: Kolom36 | AK17: Kolom37 | AL17: Kolom38 | AM17: Kolom39 | AN17: Kolom40 | AO17: Kolom41 | AP17: Kolom42 | AQ17: Kolom43 | AR17: Kolom44 | AS17: Kolom45 | AT17: Kolom46 | AU17: Kolom47 | AV17: Kolom48 | AW17: Kolom49 | AX17: Kolom50 | AY17: Kolom51 | AZ17: Kolom52 | BA17: Kolom53 | BB17: Kolom54 | BC17: Kolom55 | BD17: Kolom56 | BE17: Kolom57 | BF17: Kolom58 | BG17: Kolom59 | BH17: Kolom60 | BI17: Kolom61 | BJ17: Kolom62 | BK17: Kolom63 | BL17: Kolom64 | BM17: Kolom65 | BN17: Kolom66 | BO17: Kolom67
A18: gemmideld/maand | B18: =AVERAGE(B3:B14) -> 5420.3608 | C18: =AVERAGE(C3:C14) -> -817.45273 | D18: =AVERAGE(D3:D14) -> -810.65 | E18: =AVERAGE(E3:E14) -> -567.14636 | F18: =AVERAGE(F3:F14) -> -102.62 | G18: =AVERAGE(G3:G14) -> -127.855 | H18: =AVERAGE(H3:H14) -> -87.37 | I18: =AVERAGE(I3:I14) -> -139.34 | ... BN18: =AVERAGE(BN3:BN14) -> -93.316667
A19: gemmideld/maand | B19: =ABS(B18) -> 5420.3608 | C19: =ABS(C18) -> 817.45273 | D19: =ABS(D18) -> 810.65 | E19: =ABS(E18) -> 567.14636 | F19: =ABS(F18) -> 102.62 | G19: =ABS(G18) -> 127.855 | H19: =ABS(H18) -> 87.37 | I19: =ABS(I18) -> 139.34 | ... BN19: =ABS(BN18) -> 93.316667
A20: % | B20: =B21/GETPIVOTDATA("Bedrag +/-",$A$1,"maand","augustus ","categorie","Inkomsten Loon") -> #REF! | C20: =C21/GETPIVOTDATA("Bedrag +/-",$A$1,"maand","augustus ","categorie","Inkomsten Loon") -> 0.05956989 | D20: =D21/GETPIVOTDATA("Bedrag +/-",$A$1,"maand","augustus ","categorie","Inkomsten Loon") -> 0.17909851 | E20: =E21/GETPIVOTDATA("Bedrag +/-",$A$1,"maand","augustus ","categorie","Inkomsten Loon") -> 0 | F20: =F21/GETPIVOTDATA("Bedrag +/-",$A$1,"maand","augustus ","categorie","Inkomsten Loon") -> 0.016348966 | G20: =G21/GETPIVOTDATA("Bedrag +/-",$A$1,"maand","augustus ","categorie","Inkomsten Loon") -> 0 | H20: =H21/GETPIVOTDATA("Bedrag +/-",$A$1,"maand","augustus ","categorie","Inkomsten Loon") -> 0.0099971721 | I20: =I21/GETPIVOTDATA("Bedrag +/-",$A$1,"maand","augustus ","categorie","Inkomsten Loon") -> 0.012405331 | ... BN20: =BN21/GETPIVOTDATA("Bedrag +/-",$A$1,"maand","augustus ","categorie","Inkomsten Loon") -> 0
A21: reeds verbruikt | B21: =SUM(#REF!) -> #REF! | C21: 269.63 | D21: 810.65 | F21: 74 | H21: 45.25 | I21: 56.15 | K21: 211.85 | M21: 5 | P21: 125.81 | R21: 35.69 | U21: 54.4 | V21: 12.01 | X21: 414.43 | Y21: 20.71 | Z21: 11.94 | AB21: 12.5 | AC21: 100.1 | AE21: 113.81 | AG21: 57.94 | AH21: 19.4 | AI21: 0 | AJ21: 13.99 | AL21: 2 | AQ21: 6.93 | AR21: 166.16 | AU21: 25 | AY21: 91.89 | BB21: 12
A22: saldo | C22: =C19-C21 -> 547.82273 | D22: =D19-D21 -> 0 | E22: =E19-E21 -> 567.14636 | F22: =F19-F21 -> 28.62 | G22: =G19-G21 -> 127.855 | H22: =H19-H21 -> 42.12 | I22: =I19-I21 -> 83.19 | J22: =J19-J21 -> 82.79375 | ... BN22: =BN19-BN21 -> 93.316667
A23: % verbruikt | B23: =B21/B19 -> #REF! | C23: =C21/C19 -> 0.3298417 | D23: =D21/D19 -> 1 | E23: =E21/E19 -> 0 | F23: =F21/F19 -> 0.721107 | G23: =G21/G19 -> 0 | H23: =H21/H19 -> 0.51791233 | I23: =I21/I19 -> 0.40297115 | ... BN23: =BN21/BN19 -> 0
BB26: volgende keer eind oktober
BD27: nieuwsblad

Sheet Score
A1: Totale inkomsten (maand) | B1: =AVERAGE(Dashboard!C8:N8) -> 5420.3608 | D1: Spaargedrag (≥10% van inkomen) | E1: =IF(B3/B1>=0.1,20,10) -> 10
A2: totale uitgaven (maand) | B2: =ABS(C2) -> 4943.1892 | C2: =(GETPIVOTDATA("Bedrag +/-",Dashboard!$A$5,"vast/variabel","Vast")+GETPIVOTDATA("Bedrag +/-",Dashboard!$A$5,"vast/variabel","Variabel"))/12 -> -4943.1892 | D2: Vaste lasten ≤ 50% van inkomen | E2: =IF(B4/B1<=0.5,20,IF(B4/B1<=0.7,10,0)) -> 20
A3: Gespaard bedrag (maand) | B3: 75 | D3: Meer inkomsten dan uitgaven | E3: =IF(B1>B2,20,0) -> 20
A4: Vaste lasten (maand) | B4: =ABS(C4) -> 40.245455 | C4: =AVERAGE(Dashboard!C33:N33) -> -40.245455 | D4: Buffer ≥ 3x maanduitgaven | E4: =IF(B5/B2>=3,20,IF(B5/B2>=1,10,0)) -> 0
A5: Spaarrekening totaal | B5: =3114.57+675.31 -> 3789.88 | D5: Geen of lage schulden | E5: =IF(B6=0,20,IF(B6/B1<0.3,10,0)) -> 20
A6: Totaal schulden | B6: 0
D7: Totale score | E7: =E1+E2+E3+E4+E5 -> 70
D8: Beoordeling | E8: =IF(E7>=80,"Topvorm 💪",IF(E7>=50,"Goed bezig 👍","Let op je geld 🚨")) -> Goed bezig 👍

Sheet Kredietscore
A1: Maandinkomen | B1: =AVERAGE(Dashboard!C8:N8) -> 5420.3608
A2: Vaste lasten per maand | B2: =ABS(C2) -> 40.245455 | C2: =AVERAGE(Dashboard!C33:N33) -> -40.245455
A3: Schulden totaal | B3: 0
A4: Spaarsaldo | B4: =Score!B5 -> 3789.88
A5: gemiddeld maandsaldo over 11 maand | B5: =ABS(C5) -> 477.17167 | C5: =AVERAGE(Dashboard!C74:N74) -> 477.17167
A6: Betalingsachterstanden | B6: nee
B8: =IF(B2/B1<=0.5,20,IF(B2/B1<=0.7,10,0)) + IF(B6="Nee",20,0) + IF(B3/(B1*12)<=0.3,20,IF(B3/(B1*12)<=0.5,10,0)) + IF(B5>0,20,0) + IF(B4/B1>=3,20,IF(B4/B1>=1,10,0)) -> 80
B9: =IF(B8>=80,"✅ Kredietwaardig",IF(B8>=50,"⚠️ Redelijk","❌ Risico")) -> ✅ Kredietwaardig

Sheet Nutsvoorziening
A1: maand | B1: water (m³) | C1: Water (m³) netto | D1: opmerkingen
A2: januari | B2: 100 | D2: netto verbruik met december manueel uitrekenen
A3: februari | B3: 105 | C3: =Tabel3[[#This Row],[water (m³)]]-B2/1000 -> 104.9
A4: maart | B4: 115 | C4: =Tabel3[[#This Row],[water (m³)]]-B3/1000 -> 114.895
A5: april | B5: 130 | C5: =Tabel3[[#This Row],[water (m³)]]-B4/1000 -> 129.885
A6: mei | B6: 150 | C6: =Tabel3[[#This Row],[water (m³)]]-B5/1000 -> 149.87
A7: juni | B7: 175 | C7: =Tabel3[[#This Row],[water (m³)]]-B6/1000 -> 174.85
A8: juli | B8: 176 | C8: =Tabel3[[#This Row],[water (m³)]]-B7/1000 -> 175.825
A9: augustus | B9: 722 | C9: =Tabel3[[#This Row],[water (m³)]]-B8/1000 -> 721.824
A10: september | B10: 280 | C10: =Tabel3[[#This Row],[water (m³)]]-B9/1000 -> 279.278
A11: oktober | B11: 325 | C11: =Tabel3[[#This Row],[water (m³)]]-B10/1000 -> 324.72
A12: november | B12: 375 | C12: =Tabel3[[#This Row],[water (m³)]]-B11/1000 -> 374.675
A13: december | B13: 430 | C13: =Tabel3[[#This Row],[water (m³)]]-B12/1000 -> 429.625

Sheet Lijst
A1: categorie | B1: type | C1: +/-
A2: Action | B2: Variabel | C2: Uitgave
A3: afbetaling fiets | B3: Vast | C3: Uitgave
A4: Allerlei | B4: Variabel | C4: Te Bepalen
A5: Amazon | B5: Variabel | C5: Uitgave
A6: automaat De Lijn | B6: Variabel | C6: Uitgave
A7: AVA | B7: Variabel | C7: Uitgave
A8: AXA | B8: Vast | C8: Uitgave
A9: Bankkost | B9: Vast | C9: Uitgave
A10: belasting | B10: Vast | C10: Uitgave
A11: Bol | B11: Variabel | C11: Uitgave
A12: Brico | B12: Variabel | C12: Uitgave
... A69: Auto onderhoud | B69: Variabel | C69: Uitgave

Sheet Trefwoorden
A1: trefwoord | B1: category
A2: SPAR | B2: voeding
A3: LIDL | B3: voeding
A4: CONRAD | B4: =Lijst!A57 -> school Bram
A5: ACTION | B5: Action
A6: DECATHLON | B6: decathlon
A7: POISSON | B7: =Lijst!A45 -> Louis/Vis
A8: MOLECULE | B8: =Lijst!A47 -> molecule
A9: SHELL | B9: =Lijst!A42 -> Laadbeurt
A10: HULPREKENING | B10: =Lijst!A34 -> Inkomsten Loon
A11: OVO | B11: =Lijst!A42 -> Laadbeurt
A12: KBC VERZEKERINGEN REF | B12: Hospitalisatie
A13: VVM | B13: =Lijst!A34 -> Inkomsten Loon
A14: CARREFOUR | B14: =B2 -> voeding
A15: TORFS | B15: =Lijst!A38 -> kledij
A16: BOSSUWE | B16: =Lijst!A55 -> restaurant
A17: TELENET | B17: =Lijst!A60 -> Telenet
A18: LEASING | B18: =Lijst!A44 -> Leasing Auto
A19: EURO SHOP | B19: =Lijst!A24 -> EuroShop
A20: DUPONZOO | B20: =B7 -> Louis/Vis
A21: GIKS | B21: =B15 -> kledij
A22: JBC | B22: =B21 -> kledij
A23: ZALANDO PAYMENTS | B23: =Trefwoorden!B21 -> kledij
A24: BOL | B24: Bol
A25: VAN ESCH | B25: =Lijst!A51 -> Ouders Bram
A26: STD BH | B26: =Lijst!A58 -> standaardboekhandel
A27: FAMIFLORA | B27: =Lijst!A4 -> Allerlei
A28: KRUIDVAT | B28: =Lijst!A41 -> kruidvat
A29: CATTEEUW LUDOVIC | B29: voeding
A30: DREAMLAND | B30: =B27 -> Allerlei
A31: TOM&CO | B31: =B7 -> Louis/Vis
A32: ELLIS GOURMET | B32: =B16 -> restaurant
A33: AXA | B33: AXA
A34: 4411 | B34: =Lijst!A52 -> Parkeren
A35: MERIJN | B35: =Lijst!A27 -> Gezondheid
A36: VALINSOPAY | B36: =Lijst!A6 -> automaat De Lijn
A37: TARCIS | B37: =B29 -> voeding
A38: SLAGERIJ | B38: =B37 -> voeding
A39: PROXIMUS | B39: =Lijst!A28 -> GSM Bram
A40: VIJVERCENTRUM | B40: =B31 -> Louis/Vis
...
